<robot name="PA10A">

	<link name="base_link">
		<visual>
			<geometry>
				<mesh filename="package://testPA10_description/meshes/stl/S1.stl"/>
			</geometry>
			<material name="bluePA10">
				<color rgba="0.753 0.8156 1 1 "/>
			</material>
		</visual>
		<collision>
      			<geometry>
        			<cylinder length="0.6" radius="0.2"/>
      			</geometry>
  		</collision>
	</link>

	<link name="linkS2" >
		<visual>
			<geometry>
				<mesh filename="package://testPA10_description/meshes/stl/S2.stl"/>
			</geometry>
			<material name="whitePA10" >
				<color rgba="0.92 0.92 0.92 1" />
			</material>
		</visual>
		<collision>
      			<geometry>
        			<cylinder length="0.6" radius="0.2"/>
      			</geometry>
  		</collision>
	</link>

	<link name="linkS3" >
		<visual>
			<geometry>
				<mesh filename="package://testPA10_description/meshes/stl/S3.stl"/>
			</geometry>
			<material name="bluePA10" />
		</visual>
		<collision>
      			<geometry>
        			<cylinder length="0.6" radius="0.2"/>
      			</geometry>
  		</collision>
	</link>

	<link name="linkE1" >
		<visual>
			<geometry>
				<mesh filename="package://testPA10_description/meshes/stl/E1.stl"/>
			</geometry>
			<material name="whitePA10" />
		</visual>
		<collision>
      			<geometry>
        			<cylinder length="0.6" radius="0.2"/>
      			</geometry>
  		</collision>
	</link>

	<link name="linkE2">
		<visual>
			<geometry>
				<mesh filename="package://testPA10_description/meshes/stl/E2.stl"/>
			</geometry>
			<material name="bluePA10" />
		</visual>
		<collision>
      			<geometry>
        			<cylinder length="0.6" radius="0.2"/>
      			</geometry>
  		</collision>
	</link>

	<link name="linkW1" >
		<visual>
			<geometry>
				<mesh filename="package://testPA10_description/meshes/stl/W1.stl"/>
			</geometry>
			<material name="whitePA10" />
		</visual>
		<collision>
      			<geometry>
        			<cylinder length="0.6" radius="0.2"/>
      			</geometry>
  		</collision>
	</link>

	<link name="linkW2" >
		<visual>
			<geometry>
				<mesh filename="package://testPA10_description/meshes/stl/W2.stl"/>
			</geometry>
			<material name="bluePA10" />
		</visual>
		<collision>
      			<geometry>
        			<cylinder length="0.6" radius="0.2"/>
      			</geometry>
  		</collision>
	</link>

	<link name="endeffector" />

	<joint name="S1" type="revolute">
		<parent link="base_link"/>
		<child link="linkS2"/>
		<origin xyz="0 0 0.317" rpy="0 0 0" />
		<axis xyz="0 0 1" />
		<limit effort="1000.0" lower="-3.09" upper="3.09" velocity="1"/>		
	</joint>
	
	<joint name="S2" type="revolute">
		<parent link="linkS2"/>
		<child link="linkS3"/>
		<origin xyz="0 0 0" rpy="0 0 0" /> <!-- .1155" rpy="0 0 0" /-->
		<axis xyz="0 1 0" />
		<limit effort="1000.0" lower="-1.59" upper="1.59" velocity="1"/>
	</joint>

	<joint name="S3" type="revolute">
		<parent link="linkS3"/>
		<child link="linkE1"/>
		<origin xyz="0 0 0.450" rpy="0 0 0" />
		<axis xyz="0 0 1" />
		<limit effort="1000.0" lower="-3.04" upper="3.04" velocity="2"/>
	</joint>

	<joint name="E1" type="revolute">
		<parent link="linkE1"/>
		<child link="linkE2"/>
		<origin xyz="0 0 0" rpy="0 0 0" />
		<axis xyz="0 1 0" />
		<limit effort="1000.0" lower="-2.39" upper="2.39" velocity="2"/>
	</joint>

	<joint name="E2" type="revolute">
		<parent link="linkE2"/>
		<child link="linkW1"/>
		<origin xyz="0 0 0.480" rpy="0 0 0" />
		<axis xyz="0 0 1" />
		<limit effort="1000.0" lower="-4.45" upper="4.45" velocity="6.28"/>
	</joint>

	<joint name="W1" type="revolute">
		<parent link="linkW1"/>
		<child link="linkW2"/>
		<origin xyz="0 0 0" rpy="0 0 0" />
		<axis xyz="0 1 0" />
		<limit effort="1000.0" lower="-2.88" upper="2.88" velocity="6.28"/>
	</joint>


	<joint name="W2" type="revolute">
		<parent link="linkW2"/>
		<child link="endeffector"/>
		<origin xyz="0 0 0.070" rpy="0 0 0" />
		<axis xyz="0 0 1" />
		<limit effort="1000.0" lower="-6.28" upper="6.28" velocity="6.28"/>
	</joint>

</robot>
		


